Workbook
Name \B: '[1]EXH4A '!#REF!
Name \B: '[1]EXH4A '!#REF!
Name \C: '[1]EXH4A '!#REF!
Name \C: '[1]EXH4A '!#REF!
Name \D: #REF!
Name \D: #REF!
Name \E: #REF!
Name \F: #REF!
Name \G: '[2]EXH-B'!#REF!
Name \I: #REF!
Name \M: '[1]EXH4A '!#REF!
Name \N: '[1]EXH4A '!#REF!
Name \p: #REF!
Name \R: #REF!
Name \S: '[2]EXH-B'!#REF!
Name \T: '[1]EXH4A '!#REF!
Name \W: '[1]EXH4A '!#REF!
Name _1: '[1]EXH4A '!#REF!
Name _2: '[1]EXH4A '!#REF!
Name _3: '[1]EXH4A '!#REF!
Name _4: '[1]EXH4A '!#REF!
Name _5: '[1]EXH4A '!#REF!
Name _6: '[1]EXH4A '!#REF!
Name _7: '[1]EXH4A '!#REF!
Name _8: '[1]EXH4A '!#REF!
Name _RTR1: #N/A
Name A: #REF!
Name AG: #REF!
Name ARL_RBR: #REF!
Name asasd: #REF!
Name Average_Annual_Capacities___Metric_Units: #REF!
Name bgp: '[2]EXH-B'!#REF!
Name BORDER1: '[3]ASC OP Rev 2 Regular Staff'!#REF!
Name C_00_RR: #REF!
Name C_02_RR: #REF!
Name C_98_RR: #REF!
Name CARH_RHS_RTR: #REF!
Name CARH_RTR: #REF!
Name case_title: '[4]Macro Inputs'!$I$4
Name cases: #REF!
Name CAT1_RHS_RBR: #REF!
Name CAT1_RHS_RTR: #REF!
Name CAT1_RHS_YR: #REF!
Name CAT2_RHS_JR: #REF!
Name CAT2_RHS_RR: #REF!
Name CAT2_RHS_RTR: #REF!
Name CatList: [5]Products!$I$5:$I$234
Name CAXL_RBR: #REF!
Name CAXL_RHS_RBR: #REF!
Name CCCR_RHS_RR: #REF!
Name CCCR_RHS_RTR: #REF!
Name CCCR_RHS_YR: #REF!
Name CCCU_RHS_JR: #REF!
Name CCCU_RHS_RTR: #REF!
Name CCR100_RTR: #REF!
Name CCR101_RTR: #REF!
Name CCR102_RTR: #REF!
Name CCR104_RTR: #REF!
Name CCR98_RTR: #REF!
Name CCRC00_YR: #REF!

Sheet Example
A2: Division | B2: SSD
A3: Function | B3: (All)
A5: Division and Function | B5: YE Headcount | C5: Workload Per Employee | D5: Cost Per Workload/Employee
A6: Domestic Recruitment
A7: 2022 | B7: 3 | C7: 34.666667 | D7: 4396.8269
A8: 2023 | B8: 5 | C8: 32.2 | D8: 4468.1988
A9: 2024 | B9: 6 | C9: 40.333333 | D9: 3086.7769
A10: 2025 | B10: 7 | C10: 23.285714 | D10: 4783.865
A11: Expat Recruitment
A12: 2022 | B12: 21 | C12: 23.809524 | D12: 9965.72
A13: 2023 | B13: 26 | C13: 18.461538 | D13: 11452.125
A14: 2024 | B14: 25 | C14: 24 | D14: 8478.3333
A15: 2025 | B15: 22 | C15: 18.181818 | D15: 11779.95

Sheet Cost Analysis Sheet
A1: Year | B1: Division | C1: Unit | D1: Function | E1: Support Group | F1: # WLD (Units or Users) | G1: Total Annual Labor Budget (by business unit) | H1: Total Annual Controllable Expenses (by business unit) | I1: Total Combined Expenses | J1: YE Unit Labor Headcount (FTE & SMP) | K1: Cost Per Support | L1: Cost per WLD/yr | M1: Cost per WLD/mo | N1: WL per Employee | O1: Cost Per WLD per Emmployee | P1: Cost per Employee | Q1: Total Function WLD | R1: Existing Direct Chargebacks - 3rd party invoices | S1: WL/T (Support Group) | T1: Est. Allocations Recorded by PAPM* | U1: Annual Projected Allocation per Model | V1: Remaining to be Allocated per Model | W1: WL/T (Total Function) | X1: Description
A2: 2022 | B2: ATPD | C2: HR Support Services | D2: CH8 Support | E2: ASC + RD | F2: ='Support Numbers'!B2 -> 40 | G2: ='Support Numbers'!B64+('BUDGET-22-25 ATPD'!Z11*0.5) -> 150000 | H2: =('BUDGET-22-25 ATPD'!Z22-'BUDGET-22-25 ATPD'!Z13-'BUDGET-22-25 ATPD'!Z12)*0.5+'Support Numbers'!B80 -> 108400 | I2: =Table1[[#This Row],[Total Annual Labor Budget (by business unit)]]+Table1[[#This Row],[Total Annual Controllable Expenses (by business unit)]] -> 258400 | J2: 2 | K2: =Table1[[#This Row],['# WLD (Units or Users)]]*Table1[[#This Row],[Cost per WLD/yr]] -> 65417.722 | L2: =(G2+H2)/Q2 -> 1635.443 | M2: =L2/12 -> 136.28692 | N2: =Q2/J2 -> 79 | O2: =IF(Table1[[#This Row],[WL per Employee]]<=0,0,Table1[[#This Row],[Total Combined Expenses]]/Table1[[#This Row],[WL per Employee]]/Table1[[#This Row],[YE Unit Labor Headcount (FTE & SMP)]]) -> 1635.443 | P2: =G2/J2 -> 75000 | Q2: ='Support Numbers'!B12 -> 158 | S2: =IF(Table1[[#This Row],['# WLD (Units or Users)]]=0,0,(G2+H2)/F2) -> 6460 | W2: =(G2+H2)/Q2 -> 1635.443 | X2: Onboarding, ongoing, and offboarding support of seconded CH8 employees
A3: 2022 | B3: ATPD | C3: HR Support Services | D3: CH8 Support | E3: SAEV | F3: ='Support Numbers'!B4 -> 0 | G3: ='Support Numbers'!B64+('BUDGET-22-25 ATPD'!Z11*0.5) -> 150000 | H3: =('BUDGET-22-25 ATPD'!Z22-'BUDGET-22-25 ATPD'!Z13-'BUDGET-22-25 ATPD'!Z12)*0.5+'Support Numbers'!B80 -> 108400 | I3: =Table1[[#This Row],[Total Annual Labor Budget (by business unit)]]+Table1[[#This Row],[Total Annual Controllable Expenses (by business unit)]] -> 258400 | J3: 2 | K3: =Table1[[#This Row],['# WLD (Units or Users)]]*Table1[[#This Row],[Cost per WLD/yr]] -> 0 | L3: =(G3+H3)/Q3 -> 1635.443 | M3: =L3/12 -> 136.28692 | N3: =Q3/J3 -> 79 | O3: =IF(Table1[[#This Row],[WL per Employee]]<=0,0,Table1[[#This Row],[Total Combined Expenses]]/Table1[[#This Row],[WL per Employee]]/Table1[[#This Row],[YE Unit Labor Headcount (FTE & SMP)]]) -> 1635.443 | P3: =G3/J3 -> 75000 | Q3: ='Support Numbers'!B12 -> 158 | S3: =IF(Table1[[#This Row],['# WLD (Units or Users)]]=0,0,(G3+H3)/F3) -> 0 | W3: =(G3+H3)/Q3 -> 1635.443 | X3: Onboarding, ongoing, and offboarding support of seconded CH8 employees
A4: 2022 | B4: ATPD | C4: HR Support Services | D4: CH8 Support | E4: VGO | F4: ='Support Numbers'!B10 -> 0 | G4: ='Support Numbers'!B64+('BUDGET-22-25 ATPD'!Z11*0.5) -> 150000 | H4: =('BUDGET-22-25 ATPD'!Z22-'BUDGET-22-25 ATPD'!Z13-'BUDGET-22-25 ATPD'!Z12)*0.5+'Support Numbers'!B80 -> 108400 | I4: =Table1[[#This Row],[Total Annual Labor Budget (by business unit)]]+Table1[[#This Row],[Total Annual Controllable Expenses (by business unit)]] -> 258400 | J4: 2 | K4: =Table1[[#This Row],['# WLD (Units or Users)]]*Table1[[#This Row],[Cost per WLD/yr]] -> 0 | L4: =(G4+H4)/Q4 -> 1635.443 | M4: =L4/12 -> 136.28692 | N4: =Q4/J4 -> 79 | O4: =IF(Table1[[#This Row],[WL per Employee]]<=0,0,Table1[[#This Row],[Total Combined Expenses]]/Table1[[#This Row],[WL per Employee]]/Table1[[#This Row],[YE Unit Labor Headcount (FTE & SMP)]]) -> 1635.443 | P4: =G4/J4 -> 75000 | Q4: ='Support Numbers'!B12 -> 158 | S4: =IF(Table1[[#This Row],['# WLD (Units or Users)]]=0,0,(G4+H4)/F4) -> 0 | W4: =(G4+H4)/Q4 -> 1635.443 | X4: Onboarding, ongoing, and offboarding support of seconded CH8 employees
A5: 2022 | B5: ATPD | C5: HR Support Services | D5: CH8 Support | E5: Motiva | F5: ='Support Numbers'!B7 -> 2 | G5: ='Support Numbers'!B64+('BUDGET-22-25 ATPD'!Z11*0.5) -> 150000 | H5: =('BUDGET-22-25 ATPD'!Z22-'BUDGET-22-25 ATPD'!Z13-'BUDGET-22-25 ATPD'!Z12)*0.5+'Support Numbers'!B80 -> 108400 | I5: =Table1[[#This Row],[Total Annual Labor Budget (by business unit)]]+Table1[[#This Row],[Total Annual Controllable Expenses (by business unit)]] -> 258400 | J5: 2 | K5: =Table1[[#This Row],['# WLD (Units or Users)]]*Table1[[#This Row],[Cost per WLD/yr]] -> 3270.8861 | L5: =(G5+H5)/Q5 -> 1635.443 | M5: =L5/12 -> 136.28692 | N5: =Q5/J5 -> 79 | O5: =IF(Table1[[#This Row],[WL per Employee]]<=0,0,Table1[[#This Row],[Total Combined Expenses]]/Table1[[#This Row],[WL per Employee]]/Table1[[#This Row],[YE Unit Labor Headcount (FTE & SMP)]]) -> 1635.443 | P5: =G5/J5 -> 75000 | Q5: ='Support Numbers'!B12 -> 158 | S5: =IF(Table1[[#This Row],['# WLD (Units or Users)]]=0,0,(G5+H5)/F5) -> 129200 | W5: =(G5+H5)/Q5 -> 1635.443 | X5: Onboarding, ongoing, and offboarding support of seconded CH8 employees
A6: 2022 | B6: ATPD | C6: HR Support Services | D6: CH8 Support | E6: PMT | F6: ='Support Numbers'!B9 -> 30 | G6: ='Support Numbers'!B64+('BUDGET-22-25 ATPD'!Z11*0.5) -> 150000 | H6: =('BUDGET-22-25 ATPD'!Z22-'BUDGET-22-25 ATPD'!Z13-'BUDGET-22-25 ATPD'!Z12)*0.5+'Support Numbers'!B80 -> 108400 | I6: =Table1[[#This Row],[Total Annual Labor Budget (by business unit)]]+Table1[[#This Row],[Total Annual Controllable Expenses (by business unit)]] -> 258400 | J6: 2 | K6: =Table1[[#This Row],['# WLD (Units or Users)]]*Table1[[#This Row],[Cost per WLD/yr]] -> 49063.291 | L6: =(G6+H6)/Q6 -> 1635.443 | M6: =L6/12 -> 136.28692 | N6: =Q6/J6 -> 79 | O6: =IF(Table1[[#This Row],[WL per Employee]]<=0,0,Table1[[#This Row],[Total Combined Expenses]]/Table1[[#This Row],[WL per Employee]]/Table1[[#This Row],[YE Unit Labor Headcount (FTE & SMP)]]) -> 1635.443 | P6: =G6/J6 -> 75000 | Q6: ='Support Numbers'!B12 -> 158 | S6: =IF(Table1[[#This Row],['# WLD (Units or Users)]]=0,0,(G6+H6)/F6) -> 8613.3333 | W6: =(G6+H6)/Q6 -> 1635.443 | X6: Onboarding, ongoing, and offboarding support of seconded CH8 employees
A7: 2022 | B7: ATPD | C7: HR Support Services | D7: CH8 Support | E7: SRI | F7: ='Support Numbers'!B6 -> 2 | G7: ='Support Numbers'!B64+('BUDGET-22-25 ATPD'!Z11*0.5) -> 150000 | H7: =('BUDGET-22-25 ATPD'!Z22-'BUDGET-22-25 ATPD'!Z13-'BUDGET-22-25 ATPD'!Z12)*0.5+'Support Numbers'!B80 -> 108400 | I7: =Table1[[#This Row],[Total Annual Labor Budget (by business unit)]]+Table1[[#This Row],[Total Annual Controllable Expenses (by business unit)]] -> 258400 | J7: 2 | K7: =Table1[[#This Row],['# WLD (Units or Users)]]*Table1[[#This Row],[Cost per WLD/yr]] -> 3270.8861 | L7: =(G7+H7)/Q7 -> 1635.443 | M7: =L7/12 -> 136.28692 | N7: =Q7/J7 -> 79 | O7: =IF(Table1[[#This Row],[WL per Employee]]<=0,0,Table1[[#This Row],[Total Combined Expenses]]/Table1[[#This Row],[WL per Employee]]/Table1[[#This Row],[YE Unit Labor Headcount (FTE & SMP)]]) -> 1635.443 | P7: =G7/J7 -> 75000 | Q7: ='Support Numbers'!B12 -> 158 | S7: =IF(Table1[[#This Row],['# WLD (Units or Users)]]=0,0,(G7+H7)/F7) -> 129200 | W7: =(G7+H7)/Q7 -> 1635.443 | X7: Onboarding, ongoing, and offboarding support of seconded CH8 employees
A8: 2022 | B8: ATPD | C8: HR Support Services | D8: CH8 Support | E8: SPII | F8: ='Support Numbers'!B8 -> 3 | G8: ='Support Numbers'!B64+('BUDGET-22-25 ATPD'!Z11*0.5) -> 150000 | H8: =('BUDGET-22-25 ATPD'!Z22-'BUDGET-22-25 ATPD'!Z13-'BUDGET-22-25 ATPD'!Z12)*0.5+'Support Numbers'!B80 -> 108400 | I8: =Table1[[#This Row],[Total Annual Labor Budget (by business unit)]]+Table1[[#This Row],[Total Annual Controllable Expenses (by business unit)]] -> 258400 | J8: 2 | K8: =Table1[[#This Row],['# WLD (Units or Users)]]*Table1[[#This Row],[Cost per WLD/yr]] -> 4906.3291 | L8: =(G8+H8)/Q8 -> 1635.443 | M8: =L8/12 -> 136.28692 | N8: =Q8/J8 -> 79 | O8: =IF(Table1[[#This Row],[WL per Employee]]<=0,0,Table1[[#This Row],[Total Combined Expenses]]/Table1[[#This Row],[WL per Employee]]/Table1[[#This Row],[YE Unit Labor Headcount (FTE & SMP)]]) -> 1635.443 | P8: =G8/J8 -> 75000 | Q8: ='Support Numbers'!B12 -> 158 | S8: =IF(Table1[[#This Row],['# WLD (Units or Users)]]=0,0,(G8+H8)/F8) -> 86133.333 | W8: =(G8+H8)/Q8 -> 1635.443 | X8: Onboarding, ongoing, and offboarding support of seconded CH8 employees
A9: 2022 | B9: ATPD | C9: HR Support Services | D9: CH8 Support | E9: NEX | F9: ='Support Numbers'!B5 -> 1 | G9: ='Support Numbers'!B64+('BUDGET-22-25 ATPD'!Z11*0.5) -> 150000 | H9: =('BUDGET-22-25 ATPD'!Z22-'BUDGET-22-25 ATPD'!Z13-'BUDGET-22-25 ATPD'!Z12)*0.5+'Support Numbers'!B80 -> 108400 | I9: =Table1[[#This Row],[Total Annual Labor Budget (by business unit)]]+Table1[[#This Row],[Total Annual Controllable Expenses (by business unit)]] -> 258400 | J9: 2 | K9: =Table1[[#This Row],['# WLD (Units or Users)]]*Table1[[#This Row],[Cost per WLD/yr]] -> 1635.443 | L9: =(G9+H9)/Q9 -> 1635.443 | M9: =L9/12 -> 136.28692 | N9: =Q9/J9 -> 79 | O9: =IF(Table1[[#This Row],[WL per Employee]]<=0,0,Table1[[#This Row],[Total Combined Expenses]]/Table1[[#This Row],[WL per Employee]]/Table1[[#This Row],[YE Unit Labor Headcount (FTE & SMP)]]) -> 1635.443 | P9: =G9/J9 -> 75000 | Q9: ='Support Numbers'!B12 -> 158 | S9: =IF(Table1[[#This Row],['# WLD (Units or Users)]]=0,0,(G9+H9)/F9) -> 258400 | W9: =(G9+H9)/Q9 -> 1635.443 | X9: Onboarding, ongoing, and offboarding support of seconded CH8 employees
A10: 2022 | B10: ATPD | C10: HR Support Services | D10: CH8 Support | E10: Internships | F10: ='Support Numbers'!B11 -> 80 | G10: ='Support Numbers'!B64+('BUDGET-22-25 ATPD'!Z11*0.5) -> 150000 | H10: =('BUDGET-22-25 ATPD'!Z22-'BUDGET-22-25 ATPD'!Z13-'BUDGET-22-25 ATPD'!Z12)*0.5+'Support Numbers'!B80 -> 108400 | I10: =Table1[[#This Row],[Total Annual Labor Budget (by business unit)]]+Table1[[#This Row],[Total Annual Controllable Expenses (by business unit)]] -> 258400 | J10: 2 | K10: =Table1[[#This Row],['# WLD (Units or Users)]]*Table1[[#This Row],[Cost per WLD/yr]] -> 130835.44 | L10: =(G10+H10)/Q10 -> 1635.443 | M10: =L10/12 -> 136.28692 | N10: =Q10/J10 -> 79 | O10: =IF(Table1[[#This Row],[WL per Employee]]<=0,0,Table1[[#This Row],[Total Combined Expenses]]/Table1[[#This Row],[WL per Employee]]/Table1[[#This Row],[YE Unit Labor Headcount (FTE & SMP)]]) -> 1635.443 | P10: =G10/J10 -> 75000 | Q10: ='Support Numbers'!B12 -> 158 | S10: =IF(Table1[[#This Row],['# WLD (Units or Users)]]=0,0,(G10+H10)/F10) -> 3230 | W10: =(G10+H10)/Q10 -> 1635.443 | X10: Onboarding, ongoing, and offboarding support of seconded CH8 employees
A11: 2022 | B11: ATPD | C11: HR Support Services | D11: Medical Referral | E11: Medical Referrals | F11: ='Support Numbers'!B19 -> 50 | G11: ='Support Numbers'!B65 -> 110000 | H11: =('BUDGET-22-25 ATPD'!Z22-'BUDGET-22-25 ATPD'!Z13-'BUDGET-22-25 ATPD'!Z12)*0.5 -> 33400 | I11: =Table1[[#This Row],[Total Annual Labor Budget (by business unit)]]+Table1[[#This Row],[Total Annual Controllable Expenses (by business unit)]] -> 143400 | J11: 1 | K11: =Table1[[#This Row],['# WLD (Units or Users)]]*Table1[[#This Row],[Cost per WLD/yr]] -> 143400 | L11: =(G11+H11)/Q11 -> 2868 | M11: =L11/12 -> 239 | N11: =Q11/J11 -> 50 | O11: =IF(Table1[[#This Row],[WL per Employee]]<=0,0,Table1[[#This Row],[Total Combined Expenses]]/Table1[[#This Row],[WL per Employee]]/Table1[[#This Row],[YE Unit Labor Headcount (FTE & SMP)]]) -> 2868 | P11: =G11/J11 -> 110000 | Q11: ='Support Numbers'!B19 -> 50 | S11: =IF(Table1[[#This Row],['# WLD (Units or Users)]]=0,0,(G11+H11)/F11) -> 2868 | W11: =(G11+H11)/Q11 -> 2868 | X11: Coordination of medical referral patience and programs
A12: 2022 | B12: ATPD | C12: HR Support Services | D12: CH14 Fin Support | E12: All Students | F12: ='Support Numbers'!B18 -> 1080 | G12: ='Support Numbers'!B66+('BUDGET-22-25 ATPD'!Z11*0.5) -> 110000 | H12: =('BUDGET-22-25 ATPD'!Z22-'BUDGET-22-25 ATPD'!Z13-'BUDGET-22-25 ATPD'!Z12)*0.5 -> 33400 | I12: =Table1[[#This Row],[Total Annual Labor Budget (by business unit)]]+Table1[[#This Row],[Total Annual Controllable Expenses (by business unit)]] -> 143400 | J12: 2.5 | K12: =Table1[[#This Row],['# WLD (Units or Users)]]*Table1[[#This Row],[Cost per WLD/yr]] -> 143400 | L12: =(G12+H12)/Q12 -> 132.77778 | M12: =L12/12 -> 11.064815 | N12: =Q12/J12 -> 432 | O12: =IF(Table1[[#This Row],[WL per Employee]]<=0,0,Table1[[#This Row],[Total Combined Expenses]]/Table1[[#This Row],[WL per Employee]]/Table1[[#This Row],[YE Unit Labor Headcount (FTE & SMP)]]) -> 132.77778 | P12: =G12/J12 -> 44000 | Q12: =F12 -> 1080 | S12: =IF(Table1[[#This Row],['# WLD (Units or Users)]]=0,0,(G12+H12)/F12) -> 132.77778 | W12: =(G12+H12)/Q12 -> 132.77778 | X12: Help desk for all students inqueries
A13: 2022 | B13: ATPD | C13: Academic Prog | D13: CH14 Advisory | E13: Undergrad | F13: ='Support Numbers'!B15 -> 800 | G13: ='BUDGET-22-25 ATPD'!N8+'BUDGET-22-25 ATPD'!N12 -> 1012000 | H13: =('BUDGET-22-25 ATPD'!N9+'BUDGET-22-25 ATPD'!N22)-'BUDGET-22-25 ATPD'!N12-'BUDGET-22-25 ATPD'!N13+'Support Numbers'!B78 -> 490800 | I13: =Table1[[#This Row],[Total Annual Labor Budget (by business unit)]]+Table1[[#This Row],[Total Annual Controllable Expenses (by business unit)]] -> 1502800 | J13: ='BUDGET-22-25 ATPD'!N40+'BUDGET-22-25 ATPD'!N42 -> 9 | K13: =Table1[[#This Row],['# WLD (Units or Users)]]*Table1[[#This Row],[Cost per WLD/yr]] -> 1113185.2 | L13: =(G13+H13)/Q13 -> 1391.4815 | M13: =L13/12 -> 115.95679 | N13: =Q13/J13 -> 120 | O13: =IF(Table1[[#This Row],[WL per Employee]]<=0,0,Table1[[#This Row],[Total Combined Expenses]]/Table1[[#This Row],[WL per Employee]]/Table1[[#This Row],[YE Unit Labor Headcount (FTE & SMP)]]) -> 1391.4815 | P13: =G13/J13 -> 112444.44 | Q13: ='Support Numbers'!B18 -> 1080 | S13: =IF(Table1[[#This Row],['# WLD (Units or Users)]]=0,0,(G13+H13)/F13) -> 1878.5 | W13: =(G13+H13)/Q13 -> 1391.4815 | X13: Academic advisory for SAO sponsored students in an Undergrad program
A14: 2022 | B14: ATPD | C14: Academic Prog | D14: CH14 Advisory | E14: Associates | F14: ='Support Numbers'!B16 -> 30 | G14: ='BUDGET-22-25 ATPD'!N8+'BUDGET-22-25 ATPD'!N12 -> 1012000 | H14: =('BUDGET-22-25 ATPD'!N9+'BUDGET-22-25 ATPD'!N22)-'BUDGET-22-25 ATPD'!N12-'BUDGET-22-25 ATPD'!N13+'Support Numbers'!B78 -> 490800 | I14: =Table1[[#This Row],[Total Annual Labor Budget (by business unit)]]+Table1[[#This Row],[Total Annual Controllable Expenses (by business unit)]] -> 1502800 | J14: ='BUDGET-22-25 ATPD'!N40+'BUDGET-22-25 ATPD'!N42 -> 9 | K14: =Table1[[#This Row],['# WLD (Units or Users)]]*Table1[[#This Row],[Cost per WLD/yr]] -> 41744.444 | L14: =(G14+H14)/Q14 -> 1391.4815 | M14: =L14/12 -> 115.95679 | N14: =Q14/J14 -> 120 | O14: =IF(Table1[[#This Row],[WL per Employee]]<=0,0,Table1[[#This Row],[Total Combined Expenses]]/Table1[[#This Row],[WL per Employee]]/Table1[[#This Row],[YE Unit Labor Headcount (FTE & SMP)]]) -> 1391.4815 | P14: =G14/J14 -> 112444.44 | Q14: ='Support Numbers'!B18 -> 1080 | S14: =IF(Table1[[#This Row],['# WLD (Units or Users)]]=0,0,(G14+H14)/F14) -> 50093.333 | W14: =(G14+H14)/Q14 -> 1391.4815 | X14: Academic advisory for SAO sponsored students in an Associates program
A15: 2022 | B15: ATPD | C15: Academic Prog | D15: CH14 Advisory | E15: Advanced | F15: ='Support Numbers'!B17 -> 250 | G15: ='BUDGET-22-25 ATPD'!N8+'BUDGET-22-25 ATPD'!N12 -> 1012000 | H15: =('BUDGET-22-25 ATPD'!N9+'BUDGET-22-25 ATPD'!N22)-'BUDGET-22-25 ATPD'!N12-'BUDGET-22-25 ATPD'!N13+'Support Numbers'!B78 -> 490800 | I15: =Table1[[#This Row],[Total Annual Labor Budget (by business unit)]]+Table1[[#This Row],[Total Annual Controllable Expenses (by business unit)]] -> 1502800 | J15: ='BUDGET-22-25 ATPD'!N40+'BUDGET-22-25 ATPD'!N42 -> 9 | K15: =Table1[[#This Row],['# WLD (Units or Users)]]*Table1[[#This Row],[Cost per WLD/yr]] -> 347870.37 | L15: =(G15+H15)/Q15 -> 1391.4815 | M15: =L15/12 -> 115.95679 | N15: =Q15/J15 -> 120 | O15: =IF(Table1[[#This Row],[WL per Employee]]<=0,0,Table1[[#This Row],[Total Combined Expenses]]/Table1[[#This Row],[WL per Employee]]/Table1[[#This Row],[YE Unit Labor Headcount (FTE & SMP)]]) -> 1391.4815 | P15: =G15/J15 -> 112444.44 | Q15: ='Support Numbers'!B18 -> 1080 | S15: =IF(Table1[[#This Row],['# WLD (Units or Users)]]=0,0,(G15+H15)/F15) -> 6011.2 | W15: =(G15+H15)/Q15 -> 1391.4815 | X15: Academic advisory for SAO sponsored students in an Advanced degree program
A16: 2022 | B16: ATPD | C16: Tech Professional Unit | D16: Trainees Support | E16: CH14 | F16: ='Support Numbers'!B22 -> 25 | G16: ='BUDGET-22-25 ATPD'!T8+'BUDGET-22-25 ATPD'!T12 -> 439000 | H16: ='BUDGET-22-25 ATPD'!T9+'BUDGET-22-25 ATPD'!T22-'BUDGET-22-25 ATPD'!T12-'BUDGET-22-25 ATPD'!T13+'Support Numbers'!B79 -> 156800 | I16: =Table1[[#This Row],[Total Annual Labor Budget (by business unit)]]+Table1[[#This Row],[Total Annual Controllable Expenses (by business unit)]] -> 595800 | J16: ='BUDGET-22-25 ATPD'!T39 -> 3 | K16: =Table1[[#This Row],['# WLD (Units or Users)]]*Table1[[#This Row],[Cost per WLD/yr]] -> 297900 | L16: =(G16+H16)/Q16 -> 11916 | M16: =L16/12 -> 993 | N16: =Q16/J16 -> 16.666667 | O16: =IF(Table1[[#This Row],[WL per Employee]]<=0,0,Table1[[#This Row],[Total Combined Expenses]]/Table1[[#This Row],[WL per Employee]]/Table1[[#This Row],[YE Unit Labor Headcount (FTE & SMP)]]) -> 11916 | P16: =G16/J16 -> 146333.33 | Q16: ='Support Numbers'!B24 -> 50 | S16: =IF(Table1[[#This Row],['# WLD (Units or Users)]]=0,0,(G16+H16)/F16) -> 23832 | W16: =(G16+H16)/Q16 -> 11916 | X16: Coordination and support for sponsored CH14 trainee programs
A17: 2022 | B17: ATPD | C17: Tech Professional Unit | D17: Trainees Support | E17: CH8 | F17: ='Support Numbers'!B23 -> 25 | G17: ='BUDGET-22-25 ATPD'!T8+'BUDGET-22-25 ATPD'!T12 -> 439000 | H17: ='BUDGET-22-25 ATPD'!T9+'BUDGET-22-25 ATPD'!T22-'BUDGET-22-25 ATPD'!T12-'BUDGET-22-25 ATPD'!T13+'Support Numbers'!B79 -> 156800 | I17: =Table1[[#This Row],[Total Annual Labor Budget (by business unit)]]+Table1[[#This Row],[Total Annual Controllable Expenses (by business unit)]] -> 595800 | J17: ='BUDGET-22-25 ATPD'!T39 -> 3 | K17: =Table1[[#This Row],['# WLD (Units or Users)]]*Table1[[#This Row],[Cost per WLD/yr]] -> 297900 | L17: =(G17+H17)/Q17 -> 11916 | M17: =L17/12 -> 993 | N17: =Q17/J17 -> 16.666667 | O17: =IF(Table1[[#This Row],[WL per Employee]]<=0,0,Table1[[#This Row],[Total Combined Expenses]]/Table1[[#This Row],[WL per Employee]]/Table1[[#This Row],[YE Unit Labor Headcount (FTE & SMP)]]) -> 11916 | P17: =G17/J17 -> 146333.33 | Q17: ='Support Numbers'!B24 -> 50 | S17: =IF(Table1[[#This Row],['# WLD (Units or Users)]]=0,0,(G17+H17)/F17) -> 23832 | W17: =(G17+H17)/Q17 -> 11916 | X17: Coordination and support for sponsored CH8 trainee programs
A18: 2022 | B18: HRS | C18: All HRS | D18: HR Support Services | E18: ASC + RD | F18: ='Support Numbers'!B30 -> 500 | G18: =('BUDGET-22-25 HRS & CIG'!B8-'BUDGET-22-25 HRS & CIG'!B4) +'BUDGET-22-25 HRS & CIG'!H8+'BUDGET-22-25 HRS & CIG'!N8+'BUDGET-22-25 HRS & CIG'!T8 +'BUDGET-22-25 HRS & CIG'!B12 +'BUDGET-22-25 HRS & CIG'!H12+'BUDGET-22-25 HRS & CIG'!N12+'BUDGET-22-25 HRS & CIG'!T12 -> 2400600 | H18: =('BUDGET-22-25 HRS & CIG'!$B$22-'BUDGET-22-25 HRS & CIG'!$B$12-'BUDGET-22-25 HRS & CIG'!$B$13)+('BUDGET-22-25 HRS & CIG'!$H$22-'BUDGET-22-25 HRS & CIG'!$H$12-'BUDGET-22-25 HRS & CIG'!$H$13)+('BUDGET-22-25 HRS & CIG'!$N$22-'BUDGET-22-25 HRS & CIG'!$N$12-'BUDGET-22-25 HRS & CIG'!$N$13)+('BUDGET-22-25 HRS & CIG'!$T$22-'BUDGET-22-25 HRS & CIG'!$T$12-'BUDGET-22-25 HRS & CIG'!$T$13) -> 533500 | I18: =Table1[[#This Row],[Total Annual Labor Budget (by business unit)]]+Table1[[#This Row],[Total Annual Controllable Expenses (by business unit)]] -> 2934100 | J18: ='BUDGET-22-25 HRS & CIG'!B37+'BUDGET-22-25 HRS & CIG'!H37+'BUDGET-22-25 HRS & CIG'!N37+'BUDGET-22-25 HRS & CIG'!T37 -> 16 | K18: =Table1[[#This Row],['# WLD (Units or Users)]]*Table1[[#This Row],[Cost per WLD/yr]] -> 2629121.9 | L18: =(G18+H18)/Q18 -> 5258.2437 | M18: =L18/12 -> 438.18698 | N18: =Q18/J18 -> 34.875 | O18: =IF(Table1[[#This Row],[WL per Employee]]<=0,0,Table1[[#This Row],[Total Combined Expenses]]/Table1[[#This Row],[WL per Employee]]/Table1[[#This Row],[YE Unit Labor Headcount (FTE & SMP)]]) -> 5258.2437 | P18: =G18/J18 -> 150037.5 | Q18: ='Support Numbers'!B36 -> 558 | S18: =IF(Table1[[#This Row],['# WLD (Units or Users)]]=0,0,(G18+H18)/F18) -> 5868.2 | W18: =(G18+H18)/Q18 -> 5258.2437 | X18: Full life cycle HR support - hire to retire (onboarding, HRIS, personnel, training, offboarding) for ASC/RD employees, temps, independent contractors
A19: 2022 | B19: HRS | C19: All HRS | D19: HR Support Services | E19: AAC | F19: ='Support Numbers'!B27 -> 10 | G19: =('BUDGET-22-25 HRS & CIG'!B8-'BUDGET-22-25 HRS & CIG'!B4) +'BUDGET-22-25 HRS & CIG'!H8+'BUDGET-22-25 HRS & CIG'!N8+'BUDGET-22-25 HRS & CIG'!T8 +'BUDGET-22-25 HRS & CIG'!B12 +'BUDGET-22-25 HRS & CIG'!H12+'BUDGET-22-25 HRS & CIG'!N12+'BUDGET-22-25 HRS & CIG'!T12 -> 2400600 | H19: =('BUDGET-22-25 HRS & CIG'!$B$22-'BUDGET-22-25 HRS & CIG'!$B$12-'BUDGET-22-25 HRS & CIG'!$B$13)+('BUDGET-22-25 HRS & CIG'!$H$22-'BUDGET-22-25 HRS & CIG'!$H$12-'BUDGET-22-25 HRS & CIG'!$H$13)+('BUDGET-22-25 HRS & CIG'!$N$22-'BUDGET-22-25 HRS & CIG'!$N$12-'BUDGET-22-25 HRS & CIG'!$N$13)+('BUDGET-22-25 HRS & CIG'!$T$22-'BUDGET-22-25 HRS & CIG'!$T$12-'BUDGET-22-25 HRS & CIG'!$T$13) -> 533500 | I19: =Table1[[#This Row],[Total Annual Labor Budget (by business unit)]]+Table1[[#This Row],[Total Annual Controllable Expenses (by business unit)]] -> 2934100 | J19: ='BUDGET-22-25 HRS & CIG'!B37+'BUDGET-22-25 HRS & CIG'!H37+'BUDGET-22-25 HRS & CIG'!N37+'BUDGET-22-25 HRS & CIG'!T37 -> 16 | K19: =Table1[[#This Row],['# WLD (Units or Users)]]*Table1[[#This Row],[Cost per WLD/yr]] -> 52582.437 | L19: =(G19+H19)/Q19 -> 5258.2437 | M19: =L19/12 -> 438.18698 | N19: =Q19/J19 -> 34.875 | O19: =IF(Table1[[#This Row],[WL per Employee]]<=0,0,Table1[[#This Row],[Total Combined Expenses]]/Table1[[#This Row],[WL per Employee]]/Table1[[#This Row],[YE Unit Labor Headcount (FTE & SMP)]]) -> 5258.2437 | P19: =G19/J19 -> 150037.5 | Q19: ='Support Numbers'!B36 -> 558 | S19: =IF(Table1[[#This Row],['# WLD (Units or Users)]]=0,0,(G19+H19)/F19) -> 293410 | W19: =(G19+H19)/Q19 -> 5258.2437 | X19: Full life cycle HR support - hire to retire (onboarding, HRIS, personnel, training, offboarding) for AAC employees, temps, independent contractors
A20: 2022 | B20: HRS | C20: All HRS | D20: HR Support Services | E20: ASBCO | F20: ='Support Numbers'!B29 -> 6 | G20: =('BUDGET-22-25 HRS & CIG'!B8-'BUDGET-22-25 HRS & CIG'!B4) +'BUDGET-22-25 HRS & CIG'!H8+'BUDGET-22-25 HRS & CIG'!N8+'BUDGET-22-25 HRS & CIG'!T8 +'BUDGET-22-25 HRS & CIG'!B12 +'BUDGET-22-25 HRS & CIG'!H12+'BUDGET-22-25 HRS & CIG'!N12+'BUDGET-22-25 HRS & CIG'!T12 -> 2400600 | H20: =('BUDGET-22-25 HRS & CIG'!$B$22-'BUDGET-22-25 HRS & CIG'!$B$12-'BUDGET-22-25 HRS & CIG'!$B$13)+('BUDGET-22-25 HRS & CIG'!$H$22-'BUDGET-22-25 HRS & CIG'!$H$12-'BUDGET-22-25 HRS & CIG'!$H$13)+('BUDGET-22-25 HRS & CIG'!$N$22-'BUDGET-22-25 HRS & CIG'!$N$12-'BUDGET-22-25 HRS & CIG'!$N$13)+('BUDGET-22-25 HRS & CIG'!$T$22-'BUDGET-22-25 HRS & CIG'!$T$12-'BUDGET-22-25 HRS & CIG'!$T$13) -> 533500 | I20: =Table1[[#This Row],[Total Annual Labor Budget (by business unit)]]+Table1[[#This Row],[Total Annual Controllable Expenses (by business unit)]] -> 2934100 | J20: ='BUDGET-22-25 HRS & CIG'!B37+'BUDGET-22-25 HRS & CIG'!H37+'BUDGET-22-25 HRS & CIG'!N37+'BUDGET-22-25 HRS & CIG'!T37 -> 16 | K20: =Table1[[#This Row],['# WLD (Units or Users)]]*Table1[[#This Row],[Cost per WLD/yr]] -> 31549.462 | L20: =(G20+H20)/Q20 -> 5258.2437 | M20: =L20/12 -> 438.18698 | N20: =Q20/J20 -> 34.875 | O20: =IF(Table1[[#This Row],[WL per Employee]]<=0,0,Table1[[#This Row],[Total Combined Expenses]]/Table1[[#This Row],[WL per Employee]]/Table1[[#This Row],[YE Unit Labor Headcount (FTE & SMP)]]) -> 5258.2437 | P20: =G20/J20 -> 150037.5 | Q20: ='Support Numbers'!B36 -> 558 | S20: =IF(Table1[[#This Row],['# WLD (Units or Users)]]=0,0,(G20+H20)/F20) -> 489016.67 | W20: =(G20+H20)/Q20 -> 5258.2437 | X20: Full life cycle HR support - hire to retire (onboarding, HRIS, personnel, training, offboarding) for ASBCO employees, temps, independent contractors
A21: 2022 | B21: HRS | C21: All HRS | D21: HR Support Services | E21: APM | F21: ='Support Numbers'!B28 -> 11 | G21: =('BUDGET-22-25 HRS & CIG'!B8-'BUDGET-22-25 HRS & CIG'!B4) +'BUDGET-22-25 HRS & CIG'!H8+'BUDGET-22-25 HRS & CIG'!N8+'BUDGET-22-25 HRS & CIG'!T8 +'BUDGET-22-25 HRS & CIG'!B12 +'BUDGET-22-25 HRS & CIG'!H12+'BUDGET-22-25 HRS & CIG'!N12+'BUDGET-22-25 HRS & CIG'!T12 -> 2400600 | H21: =('BUDGET-22-25 HRS & CIG'!$B$22-'BUDGET-22-25 HRS & CIG'!$B$12-'BUDGET-22-25 HRS & CIG'!$B$13)+('BUDGET-22-25 HRS & CIG'!$H$22-'BUDGET-22-25 HRS & CIG'!$H$12-'BUDGET-22-25 HRS & CIG'!$H$13)+('BUDGET-22-25 HRS & CIG'!$N$22-'BUDGET-22-25 HRS & CIG'!$N$12-'BUDGET-22-25 HRS & CIG'!$N$13)+('BUDGET-22-25 HRS & CIG'!$T$22-'BUDGET-22-25 HRS & CIG'!$T$12-'BUDGET-22-25 HRS & CIG'!$T$13) -> 533500 | I21: =Table1[[#This Row],[Total Annual Labor Budget (by business unit)]]+Table1[[#This Row],[Total Annual Controllable Expenses (by business unit)]] -> 2934100 | J21: ='BUDGET-22-25 HRS & CIG'!B37+'BUDGET-22-25 HRS & CIG'!H37+'BUDGET-22-25 HRS & CIG'!N37+'BUDGET-22-25 HRS & CIG'!T37 -> 16 | K21: =Table1[[#This Row],['# WLD (Units or Users)]]*Table1[[#This Row],[Cost per WLD/yr]] -> 57840.681 | L21: =(G21+H21)/Q21 -> 5258.2437 | M21: =L21/12 -> 438.18698 | N21: =Q21/J21 -> 34.875 | O21: =IF(Table1[[#This Row],[WL per Employee]]<=0,0,Table1[[#This Row],[Total Combined Expenses]]/Table1[[#This Row],[WL per Employee]]/Table1[[#This Row],[YE Unit Labor Headcount (FTE & SMP)]]) -> 5258.2437 | P21: =G21/J21 -> 150037.5 | Q21: ='Support Numbers'!B36 -> 558 | S21: =IF(Table1[[#This Row],['# WLD (Units or Users)]]=0,0,(G21+H21)/F21) -> 266736.36 | W21: =(G21+H21)/Q21 -> 5258.2437 | X21: Full life cycle HR support - hire to retire (onboarding, HRIS, personnel, training, offboarding) for APM employees, temps, independent contractors
A22: 2022 | B22: HRS | C22: All HRS | D22: HR Support Services | E22: ATA | F22: ='Support Numbers'!B31 -> 0 | G22: =('BUDGET-22-25 HRS & CIG'!B8-'BUDGET-22-25 HRS & CIG'!B4) +'BUDGET-22-25 HRS & CIG'!H8+'BUDGET-22-25 HRS & CIG'!N8+'BUDGET-22-25 HRS & CIG'!T8 +'BUDGET-22-25 HRS & CIG'!B12 +'BUDGET-22-25 HRS & CIG'!H12+'BUDGET-22-25 HRS & CIG'!N12+'BUDGET-22-25 HRS & CIG'!T12 -> 2400600 | H22: =('BUDGET-22-25 HRS & CIG'!$B$22-'BUDGET-22-25 HRS & CIG'!$B$12-'BUDGET-22-25 HRS & CIG'!$B$13)+('BUDGET-22-25 HRS & CIG'!$H$22-'BUDGET-22-25 HRS & CIG'!$H$12-'BUDGET-22-25 HRS & CIG'!$H$13)+('BUDGET-22-25 HRS & CIG'!$N$22-'BUDGET-22-25 HRS & CIG'!$N$12-'BUDGET-22-25 HRS & CIG'!$N$13)+('BUDGET-22-25 HRS & CIG'!$T$22-'BUDGET-22-25 HRS & CIG'!$T$12-'BUDGET-22-25 HRS & CIG'!$T$13) -> 533500 | I22: =Table1[[#This Row],[Total Annual Labor Budget (by business unit)]]+Table1[[#This Row],[Total Annual Controllable Expenses (by business unit)]] -> 2934100 | J22: ='BUDGET-22-25 HRS & CIG'!B37+'BUDGET-22-25 HRS & CIG'!H37+'BUDGET-22-25 HRS & CIG'!N37+'BUDGET-22-25 HRS & CIG'!T37 -> 16 | K22: =Table1[[#This Row],['# WLD (Units or Users)]]*Table1[[#This Row],[Cost per WLD/yr]] -> 0 | L22: =(G22+H22)/Q22 -> 5258.2437 | M22: =L22/12 -> 438.18698 | N22: =Q22/J22 -> 34.875 | O22: =IF(Table1[[#This Row],[WL per Employee]]<=0,0,Table1[[#This Row],[Total Combined Expenses]]/Table1[[#This Row],[WL per Employee]]/Table1[[#This Row],[YE Unit Labor Headcount (FTE & SMP)]]) -> 5258.2437 | P22: =G22/J22 -> 150037.5 | Q22: ='Support Numbers'!B36 -> 558 | S22: =IF(Table1[[#This Row],['# WLD (Units or Users)]]=0,0,(G22+H22)/F22) -> 0 | W22: =(G22+H22)/Q22 -> 5258.2437 | X22: Full life cycle HR support - hire to retire (onboarding, HRIS, personnel, training, offboarding) for ATA employees, temps, independent contractors
A23: 2022 | B23: HRS | C23: All HRS | D23: HR Support Services | E23: AVMCC | F23: ='Support Numbers'!B32 -> 5 | G23: =('BUDGET-22-25 HRS & CIG'!B8-'BUDGET-22-25 HRS & CIG'!B4) +'BUDGET-22-25 HRS & CIG'!H8+'BUDGET-22-25 HRS & CIG'!N8+'BUDGET-22-25 HRS & CIG'!T8 +'BUDGET-22-25 HRS & CIG'!B12 +'BUDGET-22-25 HRS & CIG'!H12+'BUDGET-22-25 HRS & CIG'!N12+'BUDGET-22-25 HRS & CIG'!T12 -> 2400600 | H23: =('BUDGET-22-25 HRS & CIG'!$B$22-'BUDGET-22-25 HRS & CIG'!$B$12-'BUDGET-22-25 HRS & CIG'!$B$13)+('BUDGET-22-25 HRS & CIG'!$H$22-'BUDGET-22-25 HRS & CIG'!$H$12-'BUDGET-22-25 HRS & CIG'!$H$13)+('BUDGET-22-25 HRS & CIG'!$N$22-'BUDGET-22-25 HRS & CIG'!$N$12-'BUDGET-22-25 HRS & CIG'!$N$13)+('BUDGET-22-25 HRS & CIG'!$T$22-'BUDGET-22-25 HRS & CIG'!$T$12-'BUDGET-22-25 HRS & CIG'!$T$13) -> 533500 | I23: =Table1[[#This Row],[Total Annual Labor Budget (by business unit)]]+Table1[[#This Row],[Total Annual Controllable Expenses (by business unit)]] -> 2934100 | J23: ='BUDGET-22-25 HRS & CIG'!B37+'BUDGET-22-25 HRS & CIG'!H37+'BUDGET-22-25 HRS & CIG'!N37+'BUDGET-22-25 HRS & CIG'!T37 -> 16 | K23: =Table1[[#This Row],['# WLD (Units or Users)]]*Table1[[#This Row],[Cost per WLD/yr]] -> 26291.219 | L23: =(G23+H23)/Q23 -> 5258.2437 | M23: =L23/12 -> 438.18698 | N23: =Q23/J23 -> 34.875 | O23: =IF(Table1[[#This Row],[WL per Employee]]<=0,0,Table1[[#This Row],[Total Combined Expenses]]/Table1[[#This Row],[WL per Employee]]/Table1[[#This Row],[YE Unit Labor Headcount (FTE & SMP)]]) -> 5258.2437 | P23: =G23/J23 -> 150037.5 | Q23: ='Support Numbers'!B36 -> 558 | S23: =IF(Table1[[#This Row],['# WLD (Units or Users)]]=0,0,(G23+H23)/F23) -> 586820 | W23: =(G23+H23)/Q23 -> 5258.2437 | X23: Full life cycle HR support - hire to retire (onboarding, HRIS, personnel, training, offboarding) for AVMCC employees, temps, independent contractors
A24: 2022 | B24: HRS | C24: All HRS | D24: HR Support Services | E24: SAEV | F24: ='Support Numbers'!B33 -> 10 | G24: =('BUDGET-22-25 HRS & CIG'!B8-'BUDGET-22-25 HRS & CIG'!B4) +'BUDGET-22-25 HRS & CIG'!H8+'BUDGET-22-25 HRS & CIG'!N8+'BUDGET-22-25 HRS & CIG'!T8 +'BUDGET-22-25 HRS & CIG'!B12 +'BUDGET-22-25 HRS & CIG'!H12+'BUDGET-22-25 HRS & CIG'!N12+'BUDGET-22-25 HRS & CIG'!T12 -> 2400600 | H24: =('BUDGET-22-25 HRS & CIG'!$B$22-'BUDGET-22-25 HRS & CIG'!$B$12-'BUDGET-22-25 HRS & CIG'!$B$13)+('BUDGET-22-25 HRS & CIG'!$H$22-'BUDGET-22-25 HRS & CIG'!$H$12-'BUDGET-22-25 HRS & CIG'!$H$13)+('BUDGET-22-25 HRS & CIG'!$N$22-'BUDGET-22-25 HRS & CIG'!$N$12-'BUDGET-22-25 HRS & CIG'!$N$13)+('BUDGET-22-25 HRS & CIG'!$T$22-'BUDGET-22-25 HRS & CIG'!$T$12-'BUDGET-22-25 HRS & CIG'!$T$13) -> 533500 | I24: =Table1[[#This Row],[Total Annual Labor Budget (by business unit)]]+Table1[[#This Row],[Total Annual Controllable Expenses (by business unit)]] -> 2934100 | J24: ='BUDGET-22-25 HRS & CIG'!B37+'BUDGET-22-25 HRS & CIG'!H37+'BUDGET-22-25 HRS & CIG'!N37+'BUDGET-22-25 HRS & CIG'!T37 -> 16 | K24: =Table1[[#This Row],['# WLD (Units or Users)]]*Table1[[#This Row],[Cost per WLD/yr]] -> 52582.437 | L24: =(G24+H24)/Q24 -> 5258.2437 | M24: =L24/12 -> 438.18698 | N24: =Q24/J24 -> 34.875 | O24: =IF(Table1[[#This Row],[WL per Employee]]<=0,0,Table1[[#This Row],[Total Combined Expenses]]/Table1[[#This Row],[WL per Employee]]/Table1[[#This Row],[YE Unit Labor Headcount (FTE & SMP)]]) -> 5258.2437 | P24: =G24/J24 -> 150037.5 | Q24: ='Support Numbers'!B36 -> 558 | S24: =IF(Table1[[#This Row],['# WLD (Units or Users)]]=0,0,(G24+H24)/F24) -> 293410 | W24: =(G24+H24)/Q24 -> 5258.2437 | X24: Full life cycle HR support - hire to retire (onboarding, HRIS, personnel, training, offboarding) for SAEV employees, temps, independent contractors
A25: 2022 | B25: HRS | C25: All HRS | D25: HR Support Services | E25: SRI | F25: ='Support Numbers'!B34 -> 4 | G25: =('BUDGET-22-25 HRS & CIG'!B8-'BUDGET-22-25 HRS & CIG'!B4) +'BUDGET-22-25 HRS & CIG'!H8+'BUDGET-22-25 HRS & CIG'!N8+'BUDGET-22-25 HRS & CIG'!T8 +'BUDGET-22-25 HRS & CIG'!B12 +'BUDGET-22-25 HRS & CIG'!H12+'BUDGET-22-25 HRS & CIG'!N12+'BUDGET-22-25 HRS & CIG'!T12 -> 2400600 | H25: =('BUDGET-22-25 HRS & CIG'!$B$22-'BUDGET-22-25 HRS & CIG'!$B$12-'BUDGET-22-25 HRS & CIG'!$B$13)+('BUDGET-22-25 HRS & CIG'!$H$22-'BUDGET-22-25 HRS & CIG'!$H$12-'BUDGET-22-25 HRS & CIG'!$H$13)+('BUDGET-22-25 HRS & CIG'!$N$22-'BUDGET-22-25 HRS & CIG'!$N$12-'BUDGET-22-25 HRS & CIG'!$N$13)+('BUDGET-22-25 HRS & CIG'!$T$22-'BUDGET-22-25 HRS & CIG'!$T$12-'BUDGET-22-25 HRS & CIG'!$T$13) -> 533500 | I25: =Table1[[#This Row],[Total Annual Labor Budget (by business unit)]]+Table1[[#This Row],[Total Annual Controllable Expenses (by business unit)]] -> 2934100 | J25: ='BUDGET-22-25 HRS & CIG'!B37+'BUDGET-22-25 HRS & CIG'!H37+'BUDGET-22-25 HRS & CIG'!N37+'BUDGET-22-25 HRS & CIG'!T37 -> 16 | K25: =Table1[[#This Row],['# WLD (Units or Users)]]*Table1[[#This Row],[Cost per WLD/yr]] -> 21032.975 | L25: =(G25+H25)/Q25 -> 5258.2437 | M25: =L25/12 -> 438.18698 | N25: =Q25/J25 -> 34.875 | O25: =IF(Table1[[#This Row],[WL per Employee]]<=0,0,Table1[[#This Row],[Total Combined Expenses]]/Table1[[#This Row],[WL per Employee]]/Table1[[#This Row],[YE Unit Labor Headcount (FTE & SMP)]]) -> 5258.2437 | P25: =G25/J25 -> 150037.5 | Q25: ='Support Numbers'!B36 -> 558 | S25: =IF(Table1[[#This Row],['# WLD (Units or Users)]]=0,0,(G25+H25)/F25) -> 733525 | W25: =(G25+H25)/Q25 -> 5258.2437 | X25: Full life cycle HR support - hire to retire (onboarding, HRIS, personnel, training, offboarding) for SRI employees, temps, independent contractors
A26: 2022 | B26: HRS | C26: All HRS | D26: HR Support Services | E26: SPII | F26: ='Support Numbers'!B35 -> 12 | G26: =('BUDGET-22-25 HRS & CIG'!B8-'BUDGET-22-25 HRS & CIG'!B4) +'BUDGET-22-25 HRS & CIG'!H8+'BUDGET-22-25 HRS & CIG'!N8+'BUDGET-22-25 HRS & CIG'!T8 +'BUDGET-22-25 HRS & CIG'!B12 +'BUDGET-22-25 HRS & CIG'!H12+'BUDGET-22-25 HRS & CIG'!N12+'BUDGET-22-25 HRS & CIG'!T12 -> 2400600 | H26: =('BUDGET-22-25 HRS & CIG'!$B$22-'BUDGET-22-25 HRS & CIG'!$B$12-'BUDGET-22-25 HRS & CIG'!$B$13)+('BUDGET-22-25 HRS & CIG'!$H$22-'BUDGET-22-25 HRS & CIG'!$H$12-'BUDGET-22-25 HRS & CIG'!$H$13)+('BUDGET-22-25 HRS & CIG'!$N$22-'BUDGET-22-25 HRS & CIG'!$N$12-'BUDGET-22-25 HRS & CIG'!$N$13)+('BUDGET-22-25 HRS & CIG'!$T$22-'BUDGET-22-25 HRS & CIG'!$T$12-'BUDGET-22-25 HRS & CIG'!$T$13) -> 533500 | I26: =Table1[[#This Row],[Total Annual Labor Budget (by business unit)]]+Table1[[#This Row],[Total Annual Controllable Expenses (by business unit)]] -> 2934100 | J26: ='BUDGET-22-25 HRS & CIG'!B37+'BUDGET-22-25 HRS & CIG'!H37+'BUDGET-22-25 HRS & CIG'!N37+'BUDGET-22-25 HRS & CIG'!T37 -> 16 | K26: =Table1[[#This Row],['# WLD (Units or Users)]]*Table1[[#This Row],[Cost per WLD/yr]] -> 63098.925 | L26: =(G26+H26)/Q26 -> 5258.2437 | M26: =L26/12 -> 438.18698 | N26: =Q26/J26 -> 34.875 | O26: =IF(Table1[[#This Row],[WL per Employee]]<=0,0,Table1[[#This Row],[Total Combined Expenses]]/Table1[[#This Row],[WL per Employee]]/Table1[[#This Row],[YE Unit Labor Headcount (FTE & SMP)]]) -> 5258.2437 | P26: =G26/J26 -> 150037.5 | Q26: ='Support Numbers'!B36 -> 558 | S26: =IF(Table1[[#This Row],['# WLD (Units or Users)]]=0,0,(G26+H26)/F26) -> 244508.33 | W26: =(G26+H26)/Q26 -> 5258.2437 | X26: Full life cycle HR support - hire to retire (onboarding, HRIS, personnel, training, offboarding)
A27: 2022 | B27: SSD | C27: Expat Recruitment | D27: Bundled Recruitment | E27: SAO | F27: ='Support Numbers'!B50 -> 500 | G27: ='BUDGET-22-25 SSD'!B8+'BUDGET-22-25 SSD'!B12+'BUDGET-22-25 SSD'!H8+'BUDGET-22-25 SSD'!H12+'BUDGET-22-25 SSD'!N8+'BUDGET-22-25 SSD'!N12+'BUDGET-22-25 SSD'!T8+'BUDGET-22-25 SSD'!T12+'BUDGET-22-25 SSD'!Z8+'BUDGET-22-25 SSD'!Z12 -> 2337500 | H27: =('BUDGET-22-25 SSD'!B9+'BUDGET-22-25 SSD'!B22+'BUDGET-22-25 SSD'!H9+'BUDGET-22-25 SSD'!H22+'BUDGET-22-25 SSD'!N9+'BUDGET-22-25 SSD'!N22+'BUDGET-22-25 SSD'!T9+'BUDGET-22-25 SSD'!T22+'BUDGET-22-25 SSD'!Z9+'BUDGET-22-25 SSD'!Z22) -'BUDGET-22-25 SSD'!B12-'BUDGET-22-25 SSD'!B13-'BUDGET-22-25 SSD'!H12-'BUDGET-22-25 SSD'!H13-'BUDGET-22-25 SSD'!N12-'BUDGET-22-25 SSD'!N13-'BUDGET-22-25 SSD'!T12-'BUDGET-22-25 SSD'!T13-'BUDGET-22-25 SSD'!Z12-'BUDGET-22-25 SSD'!Z13 -> 2645360 | I27: =Table1[[#This Row],[Total Annual Labor Budget (by business unit)]]+Table1[[#This Row],[Total Annual Controllable Expenses (by business unit)]] -> 4982860 | J27: ='BUDGET-22-25 SSD'!B40+'BUDGET-22-25 SSD'!B42 +'BUDGET-22-25 SSD'!H40+'BUDGET-22-25 SSD'!H42 +'BUDGET-22-25 SSD'!N40+'BUDGET-22-25 SSD'!N42 +'BUDGET-22-25 SSD'!T40+'BUDGET-22-25 SSD'!T42 +'BUDGET-22-25 SSD'!Z40+'BUDGET-22-25 SSD'!Z42 -> 21 | K27: =Table1[[#This Row],['# WLD (Units or Users)]]*Table1[[#This Row],[Cost per WLD/yr]] -> 4982860 | L27: =(G27+H27)/Q27 -> 9965.72 | M27: =L27/12 -> 830.47667 | N27: =Q27/J27 -> 23.809524 | O27: =IF(Table1[[#This Row],[WL per Employee]]<=0,0,Table1[[#This Row],[Total Combined Expenses]]/Table1[[#This Row],[WL per Employee]]/Table1[[#This Row],[YE Unit Labor Headcount (FTE & SMP)]]) -> 9965.72 | P27: =G27/J27 -> 111309.52 | Q27: =F27 -> 500 | S27: =IF(Table1[[#This Row],['# WLD (Units or Users)]]=0,0,(G27+H27)/F27) -> 9965.72 | W27: =(G27+H27)/Q27 -> 9965.72 | X27: International recruitment services (sourcing, attracting, full life cycle candidate management, workshop coordination)
A28: 2022 | B28: SSD | C28: Domestic Recruitment | D28: FTE SMP Recruitment | E28: ASC + RD | F28: ='Support Numbers'!B53 -> 60 | G28: ='BUDGET-22-25 SSD'!AF8+'BUDGET-22-25 SSD'!AF12 -> 395000 | H28: =('BUDGET-22-25 SSD'!AF9+'BUDGET-22-25 SSD'!AF22)-'BUDGET-22-25 SSD'!AF12-'BUDGET-22-25 SSD'!AF13 -> 62270 | I28: =Table1[[#This Row],[Total Annual Labor Budget (by business unit)]]+Table1[[#This Row],[Total Annual Controllable Expenses (by business unit)]] -> 457270 | J28: ='BUDGET-22-25 SSD'!AF40+'BUDGET-22-25 SSD'!AF42 -> 3 | K28: =Table1[[#This Row],['# WLD (Units or Users)]]*Table1[[#This Row],[Cost per WLD/yr]] -> 263809.62 | L28: =(G28+H28)/Q28 -> 4396.8269 | M28: =L28/12 -> 366.40224 | N28: =Q28/J28 -> 34.666667 | O28: =IF(Table1[[#This Row],[WL per Employee]]<=0,0,Table1[[#This Row],[Total Combined Expenses]]/Table1[[#This Row],[WL per Employee]]/Table1[[#This Row],[YE Unit Labor Headcount (FTE & SMP)]]) -> 4396.8269 | P28: =G28/J28 -> 131666.67 | Q28: ='Support Numbers'!B61 -> 104 | S28: =IF(Table1[[#This Row],['# WLD (Units or Users)]]=0,0,(G28+H28)/F28) -> 7621.1667 | W28: =(G28+H28)/Q28 -> 4396.8269 | X28: International recruitment services (sourcing, attracting, full life cycle candidate management, workshop coordination)
A29: 2022 | B29: SSD | C29: Domestic Recruitment | D29: SMP Recruitment | E29: PMT | F29: ='Support Numbers'!B54 -> 40 | G29: ='BUDGET-22-25 SSD'!AF8+'BUDGET-22-25 SSD'!AF12 -> 395000 | H29: =('BUDGET-22-25 SSD'!AF9+'BUDGET-22-25 SSD'!AF22)-'BUDGET-22-25 SSD'!AF12-'BUDGET-22-25 SSD'!AF13 -> 62270 | I29: =Table1[[#This Row],[Total Annual Labor Budget (by business unit)]]+Table1[[#This Row],[Total Annual Controllable Expenses (by business unit)]] -> 457270 | J29: ='BUDGET-22-25 SSD'!AF40+'BUDGET-22-25 SSD'!AF42 -> 3 | K29: =Table1[[#This Row],['# WLD (Units or Users)]]*Table1[[#This Row],[Cost per WLD/yr]] -> 175873.08 | L29: =(G29+H29)/Q29 -> 4396.8269 | M29: =L29/12 -> 366.40224 | N29: =Q29/J29 -> 34.666667 | O29: =IF(Table1[[#This Row],[WL per Employee]]<=0,0,Table1[[#This Row],[Total Combined Expenses]]/Table1[[#This Row],[WL per Employee]]/Table1[[#This Row],[YE Unit Labor Headcount (FTE & SMP)]]) -> 4396.8269 | P29: =G29/J29 -> 131666.67 | Q29: ='Support Numbers'!B61 -> 104 | S29: =IF(Table1[[#This Row],['# WLD (Units or Users)]]=0,0,(G29+H29)/F29) -> 11431.75 | W29: =(G29+H29)/Q29 -> 4396.8269 | X29: Full life cycle recruitment - sourcing, attraction, proponent and candidate management
A30: 2022 | B30: SSD | C30: Domestic Recruitment | D30: FTE SMP Recruitment | E30: AVMCC | F30: ='Support Numbers'!B55 -> 0 | G30: ='BUDGET-22-25 SSD'!AF8+'BUDGET-22-25 SSD'!AF12 -> 395000 | H30: =('BUDGET-22-25 SSD'!AF9+'BUDGET-22-25 SSD'!AF22)-'BUDGET-22-25 SSD'!AF12-'BUDGET-22-25 SSD'!AF13 -> 62270 | I30: =Table1[[#This Row],[Total Annual Labor Budget (by business unit)]]+Table1[[#This Row],[Total Annual Controllable Expenses (by business unit)]] -> 457270 | J30: ='BUDGET-22-25 SSD'!AF40+'BUDGET-22-25 SSD'!AF42 -> 3 | K30: =Table1[[#This Row],['# WLD (Units or Users)]]*Table1[[#This Row],[Cost per WLD/yr]] -> 0 | L30: =(G30+H30)/Q30 -> 4396.8269 | M30: =L30/12 -> 366.40224 | N30: =Q30/J30 -> 34.666667 | O30: =IF(Table1[[#This Row],[WL per Employee]]<=0,0,Table1[[#This Row],[Total Combined Expenses]]/Table1[[#This Row],[WL per Employee]]/Table1[[#This Row],[YE Unit Labor Headcount (FTE & SMP)]]) -> 4396.8269 | P30: =G30/J30 -> 131666.67 | Q30: ='Support Numbers'!B61 -> 104 | S30: =IF(Table1[[#This Row],['# WLD (Units or Users)]]=0,0,(G30+H30)/F30) -> 0 | W30: =(G30+H30)/Q30 -> 4396.8269 | X30: Managing recruitment for temporary PMT needs - sourcing, management of agency, candidates, and proponents
A31: 2022 | B31: SSD | C31: Domestic Recruitment | D31: FTE SMP Recruitment | E31: SAEV | F31: ='Support Numbers'!B56 -> 3 | G31: ='BUDGET-22-25 SSD'!AF8+'BUDGET-22-25 SSD'!AF12 -> 395000 | H31: =('BUDGET-22-25 SSD'!AF9+'BUDGET-22-25 SSD'!AF22)-'BUDGET-22-25 SSD'!AF12-'BUDGET-22-25 SSD'!AF13 -> 62270 | I31: =Table1[[#This Row],[Total Annual Labor Budget (by business unit)]]+Table1[[#This Row],[Total Annual Controllable Expenses (by business unit)]] -> 457270 | J31: ='BUDGET-22-25 SSD'!AF40+'BUDGET-22-25 SSD'!AF42 -> 3 | K31: =Table1[[#This Row],['# WLD (Units or Users)]]*Table1[[#This Row],[Cost per WLD/yr]] -> 13190.481 | L31: =(G31+H31)/Q31 -> 4396.8269 | M31: =L31/12 -> 366.40224 | N31: =Q31/J31 -> 34.666667 | O31: =IF(Table1[[#This Row],[WL per Employee]]<=0,0,Table1[[#This Row],[Total Combined Expenses]]/Table1[[#This Row],[WL per Employee]]/Table1[[#This Row],[YE Unit Labor Headcount (FTE & SMP)]]) -> 4396.8269 | P31: =G31/J31 -> 131666.67 | Q31: ='Support Numbers'!B61 -> 104 | S31: =IF(Table1[[#This Row],['# WLD (Units or Users)]]=0,0,(G31+H31)/F31) -> 152423.33 | W31: =(G31+H31)/Q31 -> 4396.8269 | X31: Full life cycle recruitment - sourcing, attraction, proponent and candidate management
A32: 2022 | B32: SSD | C32: Domestic Recruitment | D32: FTE SMP Recruitment | E32: SPII | F32: ='Support Numbers'!B57 -> 0 | G32: ='BUDGET-22-25 SSD'!AF8+'BUDGET-22-25 SSD'!AF12 -> 395000 | H32: =('BUDGET-22-25 SSD'!AF9+'BUDGET-22-25 SSD'!AF22)-'BUDGET-22-25 SSD'!AF12-'BUDGET-22-25 SSD'!AF13 -> 62270 | I32: =Table1[[#This Row],[Total Annual Labor Budget (by business unit)]]+Table1[[#This Row],[Total Annual Controllable Expenses (by business unit)]] -> 457270 | J32: ='BUDGET-22-25 SSD'!AF40+'BUDGET-22-25 SSD'!AF42 -> 3 | K32: =Table1[[#This Row],['# WLD (Units or Users)]]*Table1[[#This Row],[Cost per WLD/yr]] -> 0 | L32: =(G32+H32)/Q32 -> 4396.8269 | M32: =L32/12 -> 366.40224 | N32: =Q32/J32 -> 34.666667 | O32: =IF(Table1[[#This Row],[WL per Employee]]<=0,0,Table1[[#This Row],[Total Combined Expenses]]/Table1[[#This Row],[WL per Employee]]/Table1[[#This Row],[YE Unit Labor Headcount (FTE & SMP)]]) -> 4396.8269 | P32: =G32/J32 -> 131666.67 | Q32: ='Support Numbers'!B61 -> 104 | S32: =IF(Table1[[#This Row],['# WLD (Units or Users)]]=0,0,(G32+H32)/F32) -> 0 | W32: =(G32+H32)/Q32 -> 4396.8269 | X32: Full life cycle recruitment - sourcing, attraction, proponent and candidate management
A33: 2022 | B33: SSD | C33: Domestic Recruitment | D33: FTE SMP Recruitment | E33: SRI | F33: ='Support Numbers'!B58 -> 0 | G33: ='BUDGET-22-25 SSD'!AF8+'BUDGET-22-25 SSD'!AF12 -> 395000 | H33: =('BUDGET-22-25 SSD'!AF9+'BUDGET-22-25 SSD'!AF22)-'BUDGET-22-25 SSD'!AF12-'BUDGET-22-25 SSD'!AF13 -> 62270 | I33: =Table1[[#This Row],[Total Annual Labor Budget (by business unit)]]+Table1[[#This Row],[Total Annual Controllable Expenses (by business unit)]] -> 457270 | J33: ='BUDGET-22-25 SSD'!AF40+'BUDGET-22-25 SSD'!AF42 -> 3 | K33: =Table1[[#This Row],['# WLD (Units or Users)]]*Table1[[#This Row],[Cost per WLD/yr]] -> 0 | L33: =(G33+H33)/Q33 -> 4396.8269 | M33: =L33/12 -> 366.40224 | N33: =Q33/J33 -> 34.666667 | O33: =IF(Table1[[#This Row],[WL per Employee]]<=0,0,Table1[[#This Row],[Total Combined Expenses]]/Table1[[#This Row],[WL per Employee]]/Table1[[#This Row],[YE Unit Labor Headcount (FTE & SMP)]]) -> 4396.8269 | P33: =G33/J33 -> 131666.67 | Q33: ='Support Numbers'!B61 -> 104 | S33: =IF(Table1[[#This Row],['# WLD (Units or Users)]]=0,0,(G33+H33)/F33) -> 0 | W33: =(G33+H33)/Q33 -> 4396.8269 | X33: Full life cycle recruitment - sourcing, attraction, proponent and candidate management
A34: 2022 | B34: SSD | C34: Domestic Recruitment | D34: FTE SMP Recruitment | E34: ASBCO | F34: ='Support Numbers'!B59 -> 1 | G34: ='BUDGET-22-25 SSD'!AF8+'BUDGET-22-25 SSD'!AF12 -> 395000 | H34: =('BUDGET-22-25 SSD'!AF9+'BUDGET-22-25 SSD'!AF22)-'BUDGET-22-25 SSD'!AF12-'BUDGET-22-25 SSD'!AF13 -> 62270 | I34: =Table1[[#This Row],[Total Annual Labor Budget (by business unit)]]+Table1[[#This Row],[Total Annual Controllable Expenses (by business unit)]] -> 457270 | J34: ='BUDGET-22-25 SSD'!AF40+'BUDGET-22-25 SSD'!AF42 -> 3 | K34: =Table1[[#This Row],['# WLD (Units or Users)]]*Table1[[#This Row],[Cost per WLD/yr]] -> 4396.8269 | L34: =(G34+H34)/Q34 -> 4396.8269 | M34: =L34/12 -> 366.40224 | N34: =Q34/J34 -> 34.666667 | O34: =IF(Table1[[#This Row],[WL per Employee]]<=0,0,Table1[[#This Row],[Total Combined Expenses]]/Table1[[#This Row],[WL per Employee]]/Table1[[#This Row],[YE Unit Labor Headcount (FTE & SMP)]]) -> 4396.8269 | P34: =G34/J34 -> 131666.67 | Q34: ='Support Numbers'!B61 -> 104 | S34: =IF(Table1[[#This Row],['# WLD (Units or Users)]]=0,0,(G34+H34)/F34) -> 457270 | W34: =(G34+H34)/Q34 -> 4396.8269 | X34: Full life cycle recruitment - sourcing, attraction, proponent and candidate management
A35: 2022 | B35: SSD | C35: Domestic Recruitment | D35: FTE SMP Recruitment | E35: ATA | F35: ='Support Numbers'!B60 -> 0 | G35: ='BUDGET-22-25 SSD'!AF8+'BUDGET-22-25 SSD'!AF12 -> 395000 | H35: =('BUDGET-22-25 SSD'!AF9+'BUDGET-22-25 SSD'!AF22)-'BUDGET-22-25 SSD'!AF12-'BUDGET-22-25 SSD'!AF13 -> 62270 | I35: =Table1[[#This Row],[Total Annual Labor Budget (by business unit)]]+Table1[[#This Row],[Total Annual Controllable Expenses (by business unit)]] -> 457270 | J35: ='BUDGET-22-25 SSD'!AF40+'BUDGET-22-25 SSD'!AF42 -> 3 | K35: =Table1[[#This Row],['# WLD (Units or Users)]]*Table1[[#This Row],[Cost per WLD/yr]] -> 0 | L35: =(G35+H35)/Q35 -> 4396.8269 | M35: =L35/12 -> 366.40224 | N35: =Q35/J35 -> 34.666667 | O35: =IF(Table1[[#This Row],[WL per Employee]]<=0,0,Table1[[#This Row],[Total Combined Expenses]]/Table1[[#This Row],[WL per Employee]]/Table1[[#This Row],[YE Unit Labor Headcount (FTE & SMP)]]) -> 4396.8269 | P35: =G35/J35 -> 131666.67 | Q35: ='Support Numbers'!B61 -> 104 | S35: =IF(Table1[[#This Row],['# WLD (Units or Users)]]=0,0,(G35+H35)/F35) -> 0 | W35: =(G35+H35)/Q35 -> 4396.8269 | X35: Full life cycle recruitment - sourcing, attraction, proponent and candidate management
A36: 2022 | B36: CIG | C36: Background Investigations | D36: Expat Hiring | E36: SAO HR SSD | F36: ='Support Numbers'!B70 -> 300 | G36: ='BUDGET-22-25 HRS & CIG'!AF8+'BUDGET-22-25 HRS & CIG'!AF12 -> 410000 | H36: ='BUDGET-22-25 HRS & CIG'!AF9+'BUDGET-22-25 HRS & CIG'!AF22-'BUDGET-22-25 HRS & CIG'!AF12 -> 2004900 | I36: =Table1[[#This Row],[Total Annual Labor Budget (by business unit)]]+Table1[[#This Row],[Total Annual Controllable Expenses (by business unit)]] -> 2414900 | J36: ='BUDGET-22-25 HRS & CIG'!AF38-'BUDGET-22-25 HRS & CIG'!AF40 -> 4 | K36: =Table1[[#This Row],['# WLD (Units or Users)]]*Table1[[#This Row],[Cost per WLD/yr]] -> 452793.75 | L36: =(G36+H36)/Q36 -> 1509.3125 | M36: =L36/12 -> 125.77604 | N36: =Q36/J36 -> 400 | O36: =IF(Table1[[#This Row],[WL per Employee]]<=0,0,Table1[[#This Row],[Total Combined Expenses]]/Table1[[#This Row],[WL per Employee]]/Table1[[#This Row],[YE Unit Labor Headcount (FTE & SMP)]]) -> 1509.3125 | P36: =G36/J36 -> 102500 | Q36: ='Support Numbers'!B74 -> 1600 | S36: =IF(Table1[[#This Row],['# WLD (Units or Users)]]=0,0,(G36+H36)/F36) -> 8049.6667 | W36: =(G36+H36)/Q36 -> 1509.3125 | X36: Background checks initated for candidates consenting to checking at time of technically qualified and all candidates at offer accepted.
A37: 2022 | B37: CIG | C37: Background Investigations | D37: Domestic | E37: ASC+ATA | F37: ='Support Numbers'!B71 -> 150 | G37: ='BUDGET-22-25 HRS & CIG'!AF8+'BUDGET-22-25 HRS & CIG'!AF12 -> 410000 | H37: ='BUDGET-22-25 HRS & CIG'!AF9+'BUDGET-22-25 HRS & CIG'!AF22-'BUDGET-22-25 HRS & CIG'!AF12 -> 2004900 | I37: =Table1[[#This Row],[Total Annual Labor Budget (by business unit)]]+Table1[[#This Row],[Total Annual Controllable Expenses (by business unit)]] -> 2414900 | J37: ='BUDGET-22-25 HRS & CIG'!AF38-'BUDGET-22-25 HRS & CIG'!AF40 -> 4 | K37: =Table1[[#This Row],['# WLD (Units or Users)]]*Table1[[#This Row],[Cost per WLD/yr]] -> 226396.88 | L37: =(G37+H37)/Q37 -> 1509.3125 | M37: =L37/12 -> 125.77604 | N37: =Q37/J37 -> 400 | O37: =IF(Table1[[#This Row],[WL per Employee]]<=0,0,Table1[[#This Row],[Total Combined Expenses]]/Table1[[#This Row],[WL per Employee]]/Table1[[#This Row],[YE Unit Labor Headcount (FTE & SMP)]]) -> 1509.3125 | P37: =G37/J37 -> 102500 | Q37: ='Support Numbers'!B74 -> 1600 | S37: =IF(Table1[[#This Row],['# WLD (Units or Users)]]=0,0,(G37+H37)/F37) -> 16099.333 | W37: =(G37+H37)/Q37 -> 1509.3125 | X37: Background checks for all domestic hiring efforts
A38: 2022 | B38: CIG | C38: Background Investigations | D38: SAO Corp Security | E38: SAO Corp Security | F38: ='Support Numbers'!B72 -> 1000 | G38: ='BUDGET-22-25 HRS & CIG'!AF8+'BUDGET-22-25 HRS & CIG'!AF12 -> 410000 | H38: ='BUDGET-22-25 HRS & CIG'!AF9+'BUDGET-22-25 HRS & CIG'!AF22-'BUDGET-22-25 HRS & CIG'!AF12 -> 2004900 | I38: =Table1[[#This Row],[Total Annual Labor Budget (by business unit)]]+Table1[[#This Row],[Total Annual Controllable Expenses (by business unit)]] -> 2414900 | J38: ='BUDGET-22-25 HRS & CIG'!AF38-'BUDGET-22-25 HRS & CIG'!AF40 -> 4 | K38: =Table1[[#This Row],['# WLD (Units or Users)]]*Table1[[#This Row],[Cost per WLD/yr]] -> 1509312.5 | L38: =(G38+H38)/Q38 -> 1509.3125 | M38: =L38/12 -> 125.77604 | N38: =Q38/J38 -> 400 | O38: =IF(Table1[[#This Row],[WL per Employee]]<=0,0,Table1[[#This Row],[Total Combined Expenses]]/Table1[[#This Row],[WL per Employee]]/Table1[[#This Row],[YE Unit Labor Headcount (FTE & SMP)]]) -> 1509.3125 | P38: =G38/J38 -> 102500 | Q38: ='Support Numbers'!B74 -> 1600 | S38: =IF(Table1[[#This Row],['# WLD (Units or Users)]]=0,0,(G38+H38)/F38) -> 2414.9 | W38: =(G38+H38)/Q38 -> 1509.3125 | X38: Background checks initiated and completed for Saudi students who studied in the US/Canada and applied for jobs at Saudi Aramco upon returning home.
A39: 2022 | B39: CIG | C39: Background Investigations | D39: Special Inv. Requests | E39: Misc. | F39: ='Support Numbers'!B73 -> 150 | G39: ='BUDGET-22-25 HRS & CIG'!AF8+'BUDGET-22-25 HRS & CIG'!AF12 -> 410000 | H39: ='BUDGET-22-25 HRS & CIG'!AF9+'BUDGET-22-25 HRS & CIG'!AF22-'BUDGET-22-25 HRS & CIG'!AF12 -> 2004900 | I39: =Table1[[#This Row],[Total Annual Labor Budget (by business unit)]]+Table1[[#This Row],[Total Annual Controllable Expenses (by business unit)]] -> 2414900 | J39: ='BUDGET-22-25 HRS & CIG'!AF38-'BUDGET-22-25 HRS & CIG'!AF40 -> 4 | K39: =Table1[[#This Row],['# WLD (Units or Users)]]*Table1[[#This Row],[Cost per WLD/yr]] -> 226396.88 | L39: =(G39+H39)/Q39 -> 1509.3125 | M39: =L39/12 -> 125.77604 | N39: =Q39/J39 -> 400 | O39: =IF(Table1[[#This Row],[WL per Employee]]<=0,0,Table1[[#This Row],[Total Combined Expenses]]/Table1[[#This Row],[WL per Employee]]/Table1[[#This Row],[YE Unit Labor Headcount (FTE & SMP)]]) -> 1509.3125 | P39: =G39/J39 -> 102500 | Q39: ='Support Numbers'!B74 -> 1600 | S39: =IF(Table1[[#This Row],['# WLD (Units or Users)]]=0,0,(G39+H39)/F39) -> 16099.333 | W39: =(G39+H39)/Q39 -> 1509.3125 | X39: Includes criminal history reports for consulates, help with relocating employees' families, and investigative consultation for stakeholders like SAEV and Audit.
A40: 2023 | B40: ATPD | C40: HR Support Services | D40: CH8 Support | E40: ASC + RD | F40: ='Support Numbers'!C2 -> 50 | G40: ='Support Numbers'!C64+('BUDGET-22-25 ATPD'!AA11*0.5) -> 245000 | H40: =(('BUDGET-22-25 ATPD'!AA22-'BUDGET-22-25 ATPD'!AA13-'BUDGET-22-25 ATPD'!AA12)*0.5)+'Support Numbers'!C80 -> 109500 | I40: =Table1[[#This Row],[Total Annual Labor Budget (by business unit)]]+Table1[[#This Row],[Total Annual Controllable Expenses (by business unit)]] -> 354500 | J40: 2.5 | K40: =Table1[[#This Row],['# WLD (Units or Users)]]*Table1[[#This Row],[Cost per WLD/yr]] -> 94786.096 | L40: =(G40+H40)/Q40 -> 1895.7219 | M40: =L40/12 -> 157.97683 | N40: =Q40/J40 -> 74.8 | O40: =IF(Table1[[#This Row],[WL per Employee]]<=0,0,Table1[[#This Row],[Total Combined Expenses]]/Table1[[#This Row],[WL per Employee]]/Table1[[#This Row],[YE Unit Labor Headcount (FTE & SMP)]]) -> 1895.7219 | P40: =G40/J40 -> 98000 | Q40: ='Support Numbers'!C12 -> 187 | S40: =IF(Table1[[#This Row],['# WLD (Units or Users)]]=0,0,(G40+H40)/F40) -> 7090 | W40: =(G40+H40)/Q40 -> 1895.7219 | X40: Onboarding, ongoing, and offboarding support of seconded CH8 employees
...

Sheet Support Numbers
A1: ATPD - Chapter 8 Employees | B1: YE Active 2022 | C1: YE Active 2023 | D1: YE Active 2024 | E1: YE Active 2025 | F1: 2026
A2: ASC & RD | B2: 40 | C2: 50 | D2: 60 | E2: 70
A3: ATA | B3: 0 | C3: 0 | D3: 0 | E3: 1
A4: SAEV | B4: 0 | C4: 0 | D4: 1 | E4: 0
A5: NEx | B5: 1 | C5: 1 | D5: 0 | E5: 0
A6: SRI | B6: 2 | C6: 0 | D6: 0 | E6: 0
A7: Motiva | B7: 2 | C7: 3 | D7: 4 | E7: 5
A8: SPI | B8: 3 | C8: 3 | D8: 0 | E8: 0
A9: PMT | B9: 30 | C9: 80 | D9: 60 | E9: 90
A10: VGO | B10: 0 | C10: 0 | D10: 2 | E10: 2
A11: Other Company Internship | B11: 80 | C11: 50 | D11: 40 | E11: 70
A12: Total Chapter 8 | B12: =SUM(B2:B11) -> 158 | C12: =SUM(C2:C11) -> 187 | D12: =SUM(D2:D11) -> 167 | E12: 179
A14: ATPD - CH14 Support | B14: Year End 2022 | C14: Year End 2023 | D14: Year End 2024 | E14: Year End 2025 | F14: 2026
A15: # of CH14 Students (CDPNE) | B15: 800 | C15: 900 | D15: 950 | E15: 1000
A16: # of CH14 Students (ASDP) | B16: 30 | C16: 40 | D16: 50 | E16: 60
A17: # of CH14 Students (ADVDEG) | B17: 250 | C17: 330 | D17: 350 | E17: 280
A18: Total # of CH14 | B18: =SUM(B15:B17) -> 1080 | C18: =SUM(C15:C17) -> 1270 | D18: =SUM(D15:D17) -> 1350 | E18: =SUM(E15:E17) -> 1340
A19: # of Medical Referrals | B19: 50 | C19: 25 | D19: 50 | E19: 50
A21: ATPD - Trainees | B21: 2022 | C21: 2023 | D21: 2024 | E21: 2025 | F21: 2026
A22: CH14 | B22: 25 | C22: 10 | D22: 20 | E22: 40
A23: Ch8 | B23: 25 | C23: 20 | D23: 20 | E23: 15
A24: Total | B24: =SUM(B22:B23) -> 50 | C24: =SUM(C22:C23) -> 30 | D24: =SUM(D22:D23) -> 40 | E24: =SUM(E22:E23) -> 55
A26: HRS Support (US$ Emp & Temp) | B26: Year-End 2022 | C26: Year-End 2023 | D26: Year-End 2024 | E26: Year-End 2025 | F26: 2026
A27: AAC-Aramco Associated Company | B27: 10 | C27: 10 | D27: 6 | E27: 5
A28: APM - Aramco Performance Materials | B28: 11 | C28: 0 | D28: 0 | E28: 0
A29: ASBC-Aramco Shared Benefit Company | B29: 6 | C29: 8 | D29: 8 | E29: 8
A30: ASC-Aramco Services Company | B30: 500 | C30: 501 | D30: 507 | E30: 515
A31: ATA-Aramco Trading Americas | B31: 0 | C31: 0 | D31: 150 | E31: 150
A32: AVMC-Aramco Vent. Mgt Consultant Co | B32: 5 | C32: 8 | D32: 12 | E32: 12
A33: SAEV-Saudi Aramco Energy Ventures | B33: 10 | C33: 11 | D33: 13 | E33: 9
A34: SRI-Saudi Refining Inc. | B34: 4 | C34: 4 | D34: 4 | E34: 3
A35: SPII | B35: 12 | C35: 15 | D35: 0 | E35: 0
A36: Grand Total | B36: =SUM(B27:B35) -> 558 | C36: =SUM(C27:C35) -> 557 | D36: =SUM(D27:D35) -> 700 | E36: 660 | F36: 660
A38: HRS Support (2025) | B38: US$ Employee | C38: Saudi Ch8 Employee | D38: Temp Personnel | E38: Contractor | F38: Grand Total
A39: AAC-Aramco Associated Company | F39: 5
A40: ASBC-Aramco Shared Benefit Company | F40: 12
A41: ASC-Aramco Services Company | F41: 664
A42: ATA-Aramco Trading Americas | F42: 269
A43: AVMC-Aramco Vent. Mgt Consultant Co | F43: 12
A44: SAEV-Saudi Aramco Energy Ventures | F44: 9
...

Sheet BUDGET-22-25 SSD
A1: GL Description | B1: 2022 Recruiting Actual | C1: 2023 Recruiting Actual | D1: 2024 Recruiting Actual | E1: 2025 Recruiting Plan | F1: 2025 Recruiting Actual | G1: Column1 | H1: 2022 Sourcing Actual | I1: 2023 Sourcing Actual | J1: 2024 Sourcing Actual | K1: 2025 Sourcing Plan | L1: 2025 Sourcing Actual | M1: Column2 | N1: 2022 Recruiting-Corporate Services Actual | O1: 2023 Recruiting-Corporate Services Actual | P1: 2024 Recruiting-Corporate Services Actual | Q1: 2025 Recruiting-Corporate Services Plan | R1: 2025 Recruiting-Corporate Services Actual | S1: 3 | T1: 2022 Relocation Actual | U1: 2023 Relocation Actual | V1: 2024 Relocation Actual | W1: 2025 Relocation Plan | X1: 2025 Relocation Actual | Y1: Column4 | Z1: 2022 Admin Actual | AA1: 2023 Admin Actual | AB1: 2024 Admin Actual | AC1: 2025 Admin Plan | AD1: 2025 Admin Actual | AE1: Column3 | AF1: 2022 Domestic Recruiting Actual | AG1: 2023 Domestic Recruiting Actual | AH1: 2024 Domestic Recruiting Actual | AI1: 2025 Domestic Recruiting Plan | AJ1: 2025 Domestic Recruiting Actual
A2: Labor - US Company Regular | B2: 760000 | C2: 570000 | D2: 285000 | F2: 285000 | H2: 380000 | I2: 380000 | J2: 190000 | L2: 285000 | N2: 0 | O2: 190000 | P2: 285000 | R2: 190000 | S2: 0 | T2: 475000 | U2: 475000 | V2: 380000 | X2: 380000 | Z2: 0 | AA2: 0 | AB2: 95000 | AD2: 0 | AF2: 190000 | AG2: 285000 | AH2: 475000 | AJ2: 475000
A3: Labor - Regular Accrual | B3: 15200 | C3: 11400 | D3: 5700 | F3: 5700 | H3: 7600 | I3: 7600 | J3: 3800 | L3: 5700 | N3: 0 | O3: 3800 | P3: 5700 | R3: 3800 | S3: 0 | T3: 9500 | U3: 9500 | V3: 7600 | X3: 7600 | Z3: 0 | AA3: 0 | AB3: 1900 | AD3: 0 | AF3: 3800 | AG3: 5700 | AH3: 9500 | AJ3: 9500
A4: Labor - Incentive Plan | B4: 0 | C4: 0 | D4: 0 | F4: 0 | H4: 0 | I4: 0 | J4: 0 | L4: 0 | N4: 0 | O4: 0 | P4: 0 | R4: 0 | T4: 0 | U4: 0 | V4: 0 | X4: 0 | Z4: 0 | AA4: 0 | AB4: 0 | AD4: 0 | AF4: 0 | AG4: 0 | AH4: 0 | AJ4: 0
